Unnamed TestSuite
  ∅ it should skip by name #1
  ✘ it should fail on timeout #2 [0/0]
  ✘ it should fail on wrong plan 1 #3 [0/0]
  ✔ it should fail on wrong plan 2 #4 [1/1]
  ✔ it should fail on multiple ends #5 [0/0]
  ✔ it should fail on assertion after end #6 [0/0]
ReferenceError: SOME_UNDEFINED_VALIABLE is not defined
    at Function.<anonymous> (test/test-fail.js:24:2)
    at nextCase (test.js:273:13)
    at Function.end (test.js:333:23)
    at Function.<anonymous> (test/test-fail.js:20:9)
    at nextCase (test.js:273:13)
    at Function.end (test.js:333:23)
    at Function.<anonymous> (test/test-fail.js:17:9)
    at nextCase (test.js:273:13)
    at end (test.js:333:23)
    at Function.testCase.plan (test.js:262:36)
  ✘ it should fail on invalid test #7 [0/0]
  ✘ it should fail on invalid assertions #8 [0/7]
Error: Unable to swap "prop"
    at Mock.swap (test.js:461:45)
    at Function.<anonymous> (test/test-fail.js:48:7)
    at nextCase (test.js:273:13)
    at Function.end (test.js:333:23)
    at Function.<anonymous> (test/test-fail.js:43:3)
    at nextCase (test.js:273:13)
    at end (test.js:333:23)
    at nextCase (test.js:276:5)
    at Function.end (test.js:333:23)
    at Function.<anonymous> (test/test-fail.js:20:9)
  ✘ it should fail on read-only swap #9 [0/0]
---
  ✘ it should fail on read-only swap #9 [0/0]
Error: Unable to swap "prop"
    at Function.<anonymous> (test/test-fail.js:48:7)
    at nextCase (test.js:273:13)
    at Function.end (test.js:333:23)
    at Function.<anonymous> (test/test-fail.js:43:3)
---
  ✘ it should fail on invalid assertions #8 [0/7]
Error: Assertion:1: equal
expected: undefined
actual:   undefined
    at Function.<anonymous> (test/test-fail.js:33:7)
    at nextCase (test.js:273:13)
    at end (test.js:333:23)
    at nextCase (test.js:276:5)
Error: Assertion:2: equal
expected: "2"
actual:   <null>{"a":Circular,"toJSON":()}
    at Function.<anonymous> (test/test-fail.js:37:3)
    at nextCase (test.js:273:13)
    at end (test.js:333:23)
    at nextCase (test.js:276:5)
Error: Assertion:3: equal
expected: /1/m
actual:   /1/
    at Function.<anonymous> (test/test-fail.js:38:3)
    at nextCase (test.js:273:13)
    at end (test.js:333:23)
    at nextCase (test.js:276:5)
Error: Assertion:4: equal
expected: []
actual:   arguments[testCase(value,message,actual,op,expected),false]
    at Function.<anonymous> (test/test-fail.js:39:3)
    at nextCase (test.js:273:13)
    at end (test.js:333:23)
    at nextCase (test.js:276:5)
Error: Assertion:5: equal
expected: [/1/,B(),{"a":Circular,"toJSON":()}]
actual:   [/1/,B{},<null>{"a":Circular,"toJSON":()}]
    at Function.<anonymous> (test/test-fail.js:40:3)
    at nextCase (test.js:273:13)
    at end (test.js:333:23)
    at nextCase (test.js:276:5)
Error: Assertion:6: 0 is truthy
    at Function.<anonymous> (test/test-fail.js:41:3)
    at nextCase (test.js:273:13)
    at end (test.js:333:23)
    at nextCase (test.js:276:5)
Error: Assertion:7: throws
    at Function.<anonymous> (test/test-fail.js:42:3)
    at nextCase (test.js:273:13)
    at end (test.js:333:23)
    at nextCase (test.js:276:5)
---
  ✘ it should fail on invalid test #7 [0/0]
ReferenceError: SOME_UNDEFINED_VALIABLE is not defined
    at Function.<anonymous> (test/test-fail.js:24:2)
    at nextCase (test.js:273:13)
    at Function.end (test.js:333:23)
    at Function.<anonymous> (test/test-fail.js:20:9)
---
  ✘ it should fail on wrong plan 1 #3 [0/0]
Error: planned 1 actual 0
    at Function.<anonymous> (test/test-fail.js:10:17)
    at nextCase (test.js:273:13)
    at Timeout.end (test.js:333:23)
    at listOnTimeout (internal/timers.js:556:17)
---
  ✘ it should fail on timeout #2 [0/0]
TIMEOUT: 1ms
...
# FAIL  tests 2, 3, 7, 8, 9
1..9
# pass  4/9 [1/8]
# skip  1
---
  ✘ it should fail on assertion after end #6 [0/1]
Error: assertion after end
    at Function.<anonymous> (test/test-fail.js:21:9)
    at nextCase (test.js:273:13)
    at Function.end (test.js:333:23)
    at Function.<anonymous> (test/test-fail.js:17:9)
...
# FAIL  tests 6
1..9
# pass  3/9 [1/8]
# skip  1
---
  ✘ it should fail on wrong plan 2 #4 [1/2]
Error: assertion after end
    at Function.<anonymous> (test/test-fail.js:13:23)
    at nextCase (test.js:273:13)
    at Function.end (test.js:333:23)
    at Function.<anonymous> (test/test-fail.js:10:17)
...
# FAIL  tests 4
1..9
# pass  2/9 [1/8]
# skip  1
1..9
# pass  2/9 [1/8]
# skip  1
---
  ✘ it should fail on multiple ends #5 [0/0]
Error: ended multiple times
    at listOnTimeout (internal/timers.js:554:17)
    at processTimers (internal/timers.js:497:7)
...
# FAIL  tests 5
1..9
# pass  1/9 [1/8]
# skip  1
